Workbook

Sheet DS Khách hàng
A1: No. | B1: Chủ đầu tư | C1: Tên chủ đầu tư | D1: Đơn vị thụ hưởng | E1: Tên đơn vị thụ hưởng | F1: Mã Đề án
B544: Bản Việt - VoiceDNA
B545: Vikki bank
B546: Vikki bank

Sheet 1.DS Dự án
A1: Mã Đề án | B1: Tên đề án | C1: Chủ nhiệm đề án | D1: Mã Sản phẩm | E1: Sản phẩm | F1: PM | G1: Start Date | H1: End Date | I1: Trạng thái dự án | J1: Giai đoạn hiện tại | K1: Đã có kế hoạch công việc?
D2: TEST | K2: =IF(COUNTIF('5.Deliverable List'!$B:$B,D2)>0,"Yes","No") -> No
K3: =IF(COUNTIF('5.Deliverable List'!$B:$B,D3)>0,"Yes","No") -> No
K4: =IF(COUNTIF('5.Deliverable List'!$B:$B,D4)>0,"Yes","No") -> No
K5: =IF(COUNTIF('5.Deliverable List'!$B:$B,D5)>0,"Yes","No") -> No
K6: =IF(COUNTIF('5.Deliverable List'!$B:$B,D6)>0,"Yes","No") -> No
K7: =IF(COUNTIF('5.Deliverable List'!$B:$B,D7)>0,"Yes","No") -> No
K8: =IF(COUNTIF('5.Deliverable List'!$B:$B,D8)>0,"Yes","No") -> No
K9: =IF(COUNTIF('5.Deliverable List'!$B:$B,D9)>0,"Yes","No") -> No
K10: =IF(COUNTIF('5.Deliverable List'!$B:$B,D10)>0,"Yes","No") -> No
K11: =IF(COUNTIF('5.Deliverable List'!$B:$B,D11)>0,"Yes","No") -> No
K12: =IF(COUNTIF('5.Deliverable List'!$B:$B,D12)>0,"Yes","No") -> No
K13: =IF(COUNTIF('5.Deliverable List'!$B:$B,D13)>0,"Yes","No") -> No
K14: =IF(COUNTIF('5.Deliverable List'!$B:$B,D14)>0,"Yes","No") -> No
K15: =IF(COUNTIF('5.Deliverable List'!$B:$B,D15)>0,"Yes","No") -> No

Sheet Config
A1: Giai đoạn | B1: Giai đoạn thành phần
A2: Tiền dự án
B3: Đề xuất
B4: Khảo sát
B5: Thuyết minh sơ bộ phần mềm | C5: Một số trường hợp cần PoC
B6: Xây dựng báo cáo nghiên cứu kinh tế & Xây dựng báo cáo chủ trương đầu tư
B7: Thầu
B8: Ký Hợp đồng
A9: Sản xuất
B10: Chưa bắt đầu
B11: Kickoff
B12: Khảo sát
B13: Phân tích yêu cầu nghiệp vụ
B14: Coding
B15: Kiểm thử nội bộ
B16: Pilot
B17: UAT
B18: Golive

Sheet 2.Tổ chức nhân sự
A1: STT | B1: Nhân sự | C1: Account | D1: Công ty | E1: Trung tâm | F1: Role | G1: Level | H1: Hình thức HĐ | I1: Hình thức làm việc | J1: Thời gian làm việc | K1: Chi trả | L1: Trạng thái làm việc
A2: =IF(ISBLANK(B2), "", ROW()-1) -> 1 | B2: Văn A
A3: =IF(ISBLANK(B3), "", ROW()-1)
A4: =IF(ISBLANK(B4), "", ROW()-1)
A5: =IF(ISBLANK(B5), "", ROW()-1)
A6: =IF(ISBLANK(B6), "", ROW()-1)
A7: =IF(ISBLANK(B7), "", ROW()-1)
A8: =IF(ISBLANK(B8), "", ROW()-1)
A9: =IF(ISBLANK(B9), "", ROW()-1)
A10: =IF(ISBLANK(B10), "", ROW()-1)
A11: =IF(ISBLANK(B11), "", ROW()-1)
A12: =IF(ISBLANK(B12), "", ROW()-1)
A13: =IF(ISBLANK(B13), "", ROW()-1)
A14: =IF(ISBLANK(B14), "", ROW()-1)
... A90: =IF(ISBLANK(B90), "", ROW()-1)

Sheet 3.Tổ chức phòng ban
A1: Trung tâm | B1: Bộ phận | C1: GĐ/Quản lý

Sheet 4.Phân bổ nguồn lực
A1: Dự án | B1: Nhân sự | C1: Vai trò trong dự án | D1: From Date | E1: To Date | F1: % | G1: T6-2025 | H1: T7-2025 | I1: T8-2025 | J1: T9-2025 | K1: T10-2025 | L1: T11-2025 | M1: T12-2025 | N1: T1-2026 | O1: T2-2026 | P1: T3-2026 | Q1: T4-2026 | R1: T5-2026 | S1: T6-2026 | T1: T7-2026 | U1: T8-2026 | V1: T9-2026 | W1: T10-2026 | X1: T11-2026 | Y1: T12-2026
C2: 1. PO, 2. PM | G2: =IFERROR(__xludf.DUMMYFUNCTION("LET( monthStart,DATE(VALUE(REGEXEXTRACT(G$1,""\d{4}"")),VALUE(REGEXEXTRACT(G$1,""T(\d+)"")),1), monthEnd,EOMONTH(monthStart,0), actualStart,MAX($D2,monthStart), actualEnd,MIN($E2,monthEnd), workingDaysInMonth,NETWORKDAYS(monthStart,monthEnd), "&"workingDaysOverlap,IF(actualStart>actualEnd,0,NETWORKDAYS(actualStart,actualEnd)), IF(workingDaysOverlap=0,"""",$F2*workingDaysOverlap/workingDaysInMonth) )"),0.0) -> 0 | H2: =IFERROR(__xludf.DUMMYFUNCTION("LET( monthStart,DATE(VALUE(REGEXEXTRACT(H$1,""\d{4}"")),VALUE(REGEXEXTRACT(H$1,""T(\d+)"")),1), monthEnd,EOMONTH(monthStart,0), actualStart,MAX($D2,monthStart), actualEnd,MIN($E2,monthEnd), workingDaysInMonth,NETWORKDAYS(monthStart,monthEnd), "&"workingDaysOverlap,IF(actualStart>actualEnd,0,NETWORKDAYS(actualStart,actualEnd)), IF(workingDaysOverlap=0,"""",$F2*workingDaysOverlap/workingDaysInMonth) )"),0.0) -> 0 | I2: =IFERROR(__xludf.DUMMYFUNCTION("LET( monthStart,DATE(VALUE(REGEXEXTRACT(I$1,""\d{4}"")),VALUE(REGEXEXTRACT(I$1,""T(\d+)"")),1), monthEnd,EOMONTH(monthStart,0), actualStart,MAX($D2,monthStart), actualEnd,MIN($E2,monthEnd), workingDaysInMonth,NETWORKDAYS(monthStart,monthEnd), "&"workingDaysOverlap,IF(actualStart>actualEnd,0,NETWORKDAYS(actualStart,actualEnd)), IF(workingDaysOverlap=0,"""",$F2*workingDaysOverlap/workingDaysInMonth) )"),0.0) -> 0 | J2: =IFERROR(__xludf.DUMMYFUNCTION("LET( monthStart,DATE(VALUE(REGEXEXTRACT(J$1,""\d{4}"")),VALUE(REGEXEXTRACT(J$1,""T(\d+)"")),1), monthEnd,EOMONTH(monthStart,0), actualStart,MAX($D2,monthStart), actualEnd,MIN($E2,monthEnd), workingDaysInMonth,NETWORKDAYS(monthStart,monthEnd), "&"workingDaysOverlap,IF(actualStart>actualEnd,0,NETWORKDAYS(actualStart,actualEnd)), IF(workingDaysOverlap=0,"""",$F2*workingDaysOverlap/workingDaysInMonth) )"),0.0) -> 0 | K2: =IFERROR(__xludf.DUMMYFUNCTION("LET( monthStart,DATE(VALUE(REGEXEXTRACT(K$1,""\d{4}"")),VALUE(REGEXEXTRACT(K$1,""T(\d+)"")),1), monthEnd,EOMONTH(monthStart,0), actualStart,MAX($D2,monthStart), actualEnd,MIN($E2,monthEnd), workingDaysInMonth,NETWORKDAYS(monthStart,monthEnd), "&"workingDaysOverlap,IF(actualStart>actualEnd,0,NETWORKDAYS(actualStart,actualEnd)), IF(workingDaysOverlap=0,"""",$F2*workingDaysOverlap/workingDaysInMonth) )"),0.0) -> 0 | L2: =IFERROR(__xludf.DUMMYFUNCTION("LET( monthStart,DATE(VALUE(REGEXEXTRACT(L$1,""\d{4}"")),VALUE(REGEXEXTRACT(L$1,""T(\d+)"")),1), monthEnd,EOMONTH(monthStart,0), actualStart,MAX($D2,monthStart), actualEnd,MIN($E2,monthEnd), workingDaysInMonth,NETWORKDAYS(monthStart,monthEnd), "&"workingDaysOverlap,IF(actualStart>actualEnd,0,NETWORKDAYS(actualStart,actualEnd)), IF(workingDaysOverlap=0,"""",$F2*workingDaysOverlap/workingDaysInMonth) )"),0.0) -> 0 | M2: =IFERROR(__xludf.DUMMYFUNCTION("LET( monthStart,DATE(VALUE(REGEXEXTRACT(M$1,""\d{4}"")),VALUE(REGEXEXTRACT(M$1,""T(\d+)"")),1), monthEnd,EOMONTH(monthStart,0), actualStart,MAX($D2,monthStart), actualEnd,MIN($E2,monthEnd), workingDaysInMonth,NETWORKDAYS(monthStart,monthEnd), "&"workingDaysOverlap,IF(actualStart>actualEnd,0,NETWORKDAYS(actualStart,actualEnd)), IF(workingDaysOverlap=0,"""",$F2*workingDaysOverlap/workingDaysInMonth) )"),0.0) -> 0 | N2: =IFERROR(__xludf.DUMMYFUNCTION("LET( monthStart,DATE(VALUE(REGEXEXTRACT(N$1,""\d{4}"")),VALUE(REGEXEXTRACT(N$1,""T(\d+)"")),1), monthEnd,EOMONTH(monthStart,0), actualStart,MAX($D2,monthStart), actualEnd,MIN($E2,monthEnd), workingDaysInMonth,NETWORKDAYS(monthStart,monthEnd), "&"workingDaysOverlap,IF(actualStart>actualEnd,0,NETWORKDAYS(actualStart,actualEnd)), IF(workingDaysOverlap=0,"""",$F2*workingDaysOverlap/workingDaysInMonth) )"),0.0) -> 0 | O2: =IFERROR(__xludf.DUMMYFUNCTION("LET( monthStart,DATE(VALUE(REGEXEXTRACT(O$1,""\d{4}"")),VALUE(REGEXEXTRACT(O$1,""T(\d+)"")),1), monthEnd,EOMONTH(monthStart,0), actualStart,MAX($D2,monthStart), actualEnd,MIN($E2,monthEnd), workingDaysInMonth,NETWORKDAYS(monthStart,monthEnd), "&"workingDaysOverlap,IF(actualStart>actualEnd,0,NETWORKDAYS(actualStart,actualEnd)), IF(workingDaysOverlap=0,"""",$F2*workingDaysOverlap/workingDaysInMonth) )"),0.0) -> 0 | P2: =IFERROR(__xludf.DUMMYFUNCTION("LET( monthStart,DATE(VALUE(REGEXEXTRACT(P$1,""\d{4}"")),VALUE(REGEXEXTRACT(P$1,""T(\d+)"")),1), monthEnd,EOMONTH(monthStart,0), actualStart,MAX($D2,monthStart), actualEnd,MIN($E2,monthEnd), workingDaysInMonth,NETWORKDAYS(monthStart,monthEnd), "&"workingDaysOverlap,IF(actualStart>actualEnd,0,NETWORKDAYS(actualStart,actualEnd)), IF(workingDaysOverlap=0,"""",$F2*workingDaysOverlap/workingDaysInMonth) )"),0.0) -> 0 | Q2: =IFERROR(__xludf.DUMMYFUNCTION("LET( monthStart,DATE(VALUE(REGEXEXTRACT(Q$1,""\d{4}"")),VALUE(REGEXEXTRACT(Q$1,""T(\d+)"")),1), monthEnd,EOMONTH(monthStart,0), actualStart,MAX($D2,monthStart), actualEnd,MIN($E2,monthEnd), workingDaysInMonth,NETWORKDAYS(monthStart,monthEnd), "&"workingDaysOverlap,IF(actualStart>actualEnd,0,NETWORKDAYS(actualStart,actualEnd)), IF(workingDaysOverlap=0,"""",$F2*workingDaysOverlap/workingDaysInMonth) )"),0.0) -> 0 | R2: =IFERROR(__xludf.DUMMYFUNCTION("LET( monthStart,DATE(VALUE(REGEXEXTRACT(R$1,""\d{4}"")),VALUE(REGEXEXTRACT(R$1,""T(\d+)"")),1), monthEnd,EOMONTH(monthStart,0), actualStart,MAX($D2,monthStart), actualEnd,MIN($E2,monthEnd), workingDaysInMonth,NETWORKDAYS(monthStart,monthEnd), "&"workingDaysOverlap,IF(actualStart>actualEnd,0,NETWORKDAYS(actualStart,actualEnd)), IF(workingDaysOverlap=0,"""",$F2*workingDaysOverlap/workingDaysInMonth) )"),0.0) -> 0 | S2: =IFERROR(__xludf.DUMMYFUNCTION("LET( monthStart,DATE(VALUE(REGEXEXTRACT(S$1,""\d{4}"")),VALUE(REGEXEXTRACT(S$1,""T(\d+)"")),1), monthEnd,EOMONTH(monthStart,0), actualStart,MAX($D2,monthStart), actualEnd,MIN($E2,monthEnd), workingDaysInMonth,NETWORKDAYS(monthStart,monthEnd), "&"workingDaysOverlap,IF(actualStart>actualEnd,0,NETWORKDAYS(actualStart,actualEnd)), IF(workingDaysOverlap=0,"""",$F2*workingDaysOverlap/workingDaysInMonth) )"),0.0) -> 0 | T2: =IFERROR(__xludf.DUMMYFUNCTION("LET( monthStart,DATE(VALUE(REGEXEXTRACT(T$1,""\d{4}"")),VALUE(REGEXEXTRACT(T$1,""T(\d+)"")),1), monthEnd,EOMONTH(monthStart,0), actualStart,MAX($D2,monthStart), actualEnd,MIN($E2,monthEnd), workingDaysInMonth,NETWORKDAYS(monthStart,monthEnd), "&"workingDaysOverlap,IF(actualStart>actualEnd,0,NETWORKDAYS(actualStart,actualEnd)), IF(workingDaysOverlap=0,"""",$F2*workingDaysOverlap/workingDaysInMonth) )"),0.0) -> 0 | U2: =IFERROR(__xludf.DUMMYFUNCTION("LET( monthStart,DATE(VALUE(REGEXEXTRACT(U$1,""\d{4}"")),VALUE(REGEXEXTRACT(U$1,""T(\d+)"")),1), monthEnd,EOMONTH(monthStart,0), actualStart,MAX($D2,monthStart), actualEnd,MIN($E2,monthEnd), workingDaysInMonth,NETWORKDAYS(monthStart,monthEnd), "&"workingDaysOverlap,IF(actualStart>actualEnd,0,NETWORKDAYS(actualStart,actualEnd)), IF(workingDaysOverlap=0,"""",$F2*workingDaysOverlap/workingDaysInMonth) )"),0.0) -> 0 | V2: =IFERROR(__xludf.DUMMYFUNCTION("LET( monthStart,DATE(VALUE(REGEXEXTRACT(V$1,""\d{4}"")),VALUE(REGEXEXTRACT(V$1,""T(\d+)"")),1), monthEnd,EOMONTH(monthStart,0), actualStart,MAX($D2,monthStart), actualEnd,MIN($E2,monthEnd), workingDaysInMonth,NETWORKDAYS(monthStart,monthEnd), "&"workingDaysOverlap,IF(actualStart>actualEnd,0,NETWORKDAYS(actualStart,actualEnd)), IF(workingDaysOverlap=0,"""",$F2*workingDaysOverlap/workingDaysInMonth) )"),0.0) -> 0 | W2: =IFERROR(__xludf.DUMMYFUNCTION("LET( monthStart,DATE(VALUE(REGEXEXTRACT(W$1,""\d{4}"")),VALUE(REGEXEXTRACT(W$1,""T(\d+)"")),1), monthEnd,EOMONTH(monthStart,0), actualStart,MAX($D2,monthStart), actualEnd,MIN($E2,monthEnd), workingDaysInMonth,NETWORKDAYS(monthStart,monthEnd), "&"workingDaysOverlap,IF(actualStart>actualEnd,0,NETWORKDAYS(actualStart,actualEnd)), IF(workingDaysOverlap=0,"""",$F2*workingDaysOverlap/workingDaysInMonth) )"),0.0) -> 0 | X2: =IFERROR(__xludf.DUMMYFUNCTION("LET( monthStart,DATE(VALUE(REGEXEXTRACT(X$1,""\d{4}"")),VALUE(REGEXEXTRACT(X$1,""T(\d+)"")),1), monthEnd,EOMONTH(monthStart,0), actualStart,MAX($D2,monthStart), actualEnd,MIN($E2,monthEnd), workingDaysInMonth,NETWORKDAYS(monthStart,monthEnd), "&"workingDaysOverlap,IF(actualStart>actualEnd,0,NETWORKDAYS(actualStart,actualEnd)), IF(workingDaysOverlap=0,"""",$F2*workingDaysOverlap/workingDaysInMonth) )"),0.0) -> 0 | Y2: =IFERROR(__xludf.DUMMYFUNCTION("LET( monthStart,DATE(VALUE(REGEXEXTRACT(Y$1,""\d{4}"")),VALUE(REGEXEXTRACT(Y$1,""T(\d+)"")),1), monthEnd,EOMONTH(monthStart,0), actualStart,MAX($D2,monthStart), actualEnd,MIN($E2,monthEnd), workingDaysInMonth,NETWORKDAYS(monthStart,monthEnd), "&"workingDaysOverlap,IF(actualStart>actualEnd,0,NETWORKDAYS(actualStart,actualEnd)), IF(workingDaysOverlap=0,"""",$F2*workingDaysOverlap/workingDaysInMonth) )"),0.0) -> 0
G3: =IFERROR(__xludf.DUMMYFUNCTION("LET( monthStart,DATE(VALUE(REGEXEXTRACT(G$1,""\d{4}"")),VALUE(REGEXEXTRACT(G$1,""T(\d+)"")),1), monthEnd,EOMONTH(monthStart,0), actualStart,MAX($D3,monthStart), actualEnd,MIN($E3,monthEnd), workingDaysInMonth,NETWORKDAYS(monthStart,monthEnd), "&"workingDaysOverlap,IF(actualStart>actualEnd,0,NETWORKDAYS(actualStart,actualEnd)), IF(workingDaysOverlap=0,"""",$F3*workingDaysOverlap/workingDaysInMonth) )"),0.0) -> 0 | H3: =IFERROR(__xludf.DUMMYFUNCTION("LET( monthStart,DATE(VALUE(REGEXEXTRACT(H$1,""\d{4}"")),VALUE(REGEXEXTRACT(H$1,""T(\d+)"")),1), monthEnd,EOMONTH(monthStart,0), actualStart,MAX($D3,monthStart), actualEnd,MIN($E3,monthEnd), workingDaysInMonth,NETWORKDAYS(monthStart,monthEnd), "&"workingDaysOverlap,IF(actualStart>actualEnd,0,NETWORKDAYS(actualStart,actualEnd)), IF(workingDaysOverlap=0,"""",$F3*workingDaysOverlap/workingDaysInMonth) )"),0.0) -> 0 | I3: =IFERROR(__xludf.DUMMYFUNCTION("LET( monthStart,DATE(VALUE(REGEXEXTRACT(I$1,""\d{4}"")),VALUE(REGEXEXTRACT(I$1,""T(\d+)"")),1), monthEnd,EOMONTH(monthStart,0), actualStart,MAX($D3,monthStart), actualEnd,MIN($E3,monthEnd), workingDaysInMonth,NETWORKDAYS(monthStart,monthEnd), "&"workingDaysOverlap,IF(actualStart>actualEnd,0,NETWORKDAYS(actualStart,actualEnd)), IF(workingDaysOverlap=0,"""",$F3*workingDaysOverlap/workingDaysInMonth) )"),0.0) -> 0 | J3: =IFERROR(__xludf.DUMMYFUNCTION("LET( monthStart,DATE(VALUE(REGEXEXTRACT(J$1,""\d{4}"")),VALUE(REGEXEXTRACT(J$1,""T(\d+)"")),1), monthEnd,EOMONTH(monthStart,0), actualStart,MAX($D3,monthStart), actualEnd,MIN($E3,monthEnd), workingDaysInMonth,NETWORKDAYS(monthStart,monthEnd), "&"workingDaysOverlap,IF(actualStart>actualEnd,0,NETWORKDAYS(actualStart,actualEnd)), IF(workingDaysOverlap=0,"""",$F3*workingDaysOverlap/workingDaysInMonth) )"),0.0) -> 0 | K3: =IFERROR(__xludf.DUMMYFUNCTION("LET( monthStart,DATE(VALUE(REGEXEXTRACT(K$1,""\d{4}"")),VALUE(REGEXEXTRACT(K$1,""T(\d+)"")),1), monthEnd,EOMONTH(monthStart,0), actualStart,MAX($D3,monthStart), actualEnd,MIN($E3,monthEnd), workingDaysInMonth,NETWORKDAYS(monthStart,monthEnd), "&"workingDaysOverlap,IF(actualStart>actualEnd,0,NETWORKDAYS(actualStart,actualEnd)), IF(workingDaysOverlap=0,"""",$F3*workingDaysOverlap/workingDaysInMonth) )"),0.0) -> 0 | L3: =IFERROR(__xludf.DUMMYFUNCTION("LET( monthStart,DATE(VALUE(REGEXEXTRACT(L$1,""\d{4}"")),VALUE(REGEXEXTRACT(L$1,""T(\d+)"")),1), monthEnd,EOMONTH(monthStart,0), actualStart,MAX($D3,monthStart), actualEnd,MIN($E3,monthEnd), workingDaysInMonth,NETWORKDAYS(monthStart,monthEnd), "&"workingDaysOverlap,IF(actualStart>actualEnd,0,NETWORKDAYS(actualStart,actualEnd)), IF(workingDaysOverlap=0,"""",$F3*workingDaysOverlap/workingDaysInMonth) )"),0.0) -> 0 | M3: =IFERROR(__xludf.DUMMYFUNCTION("LET( monthStart,DATE(VALUE(REGEXEXTRACT(M$1,""\d{4}"")),VALUE(REGEXEXTRACT(M$1,""T(\d+)"")),1), monthEnd,EOMONTH(monthStart,0), actualStart,MAX($D3,monthStart), actualEnd,MIN($E3,monthEnd), workingDaysInMonth,NETWORKDAYS(monthStart,monthEnd), "&"workingDaysOverlap,IF(actualStart>actualEnd,0,NETWORKDAYS(actualStart,actualEnd)), IF(workingDaysOverlap=0,"""",$F3*workingDaysOverlap/workingDaysInMonth) )"),0.0) -> 0 | N3: =IFERROR(__xludf.DUMMYFUNCTION("LET( monthStart,DATE(VALUE(REGEXEXTRACT(N$1,""\d{4}"")),VALUE(REGEXEXTRACT(N$1,""T(\d+)"")),1), monthEnd,EOMONTH(monthStart,0), actualStart,MAX($D3,monthStart), actualEnd,MIN($E3,monthEnd), workingDaysInMonth,NETWORKDAYS(monthStart,monthEnd), "&"workingDaysOverlap,IF(actualStart>actualEnd,0,NETWORKDAYS(actualStart,actualEnd)), IF(workingDaysOverlap=0,"""",$F3*workingDaysOverlap/workingDaysInMonth) )"),0.0) -> 0 | O3: =IFERROR(__xludf.DUMMYFUNCTION("LET( monthStart,DATE(VALUE(REGEXEXTRACT(O$1,""\d{4}"")),VALUE(REGEXEXTRACT(O$1,""T(\d+)"")),1), monthEnd,EOMONTH(monthStart,0), actualStart,MAX($D3,monthStart), actualEnd,MIN($E3,monthEnd), workingDaysInMonth,NETWORKDAYS(monthStart,monthEnd), "&"workingDaysOverlap,IF(actualStart>actualEnd,0,NETWORKDAYS(actualStart,actualEnd)), IF(workingDaysOverlap=0,"""",$F3*workingDaysOverlap/workingDaysInMonth) )"),0.0) -> 0 | P3: =IFERROR(__xludf.DUMMYFUNCTION("LET( monthStart,DATE(VALUE(REGEXEXTRACT(P$1,""\d{4}"")),VALUE(REGEXEXTRACT(P$1,""T(\d+)"")),1), monthEnd,EOMONTH(monthStart,0), actualStart,MAX($D3,monthStart), actualEnd,MIN($E3,monthEnd), workingDaysInMonth,NETWORKDAYS(monthStart,monthEnd), "&"workingDaysOverlap,IF(actualStart>actualEnd,0,NETWORKDAYS(actualStart,actualEnd)), IF(workingDaysOverlap=0,"""",$F3*workingDaysOverlap/workingDaysInMonth) )"),0.0) -> 0 | Q3: =IFERROR(__xludf.DUMMYFUNCTION("LET( monthStart,DATE(VALUE(REGEXEXTRACT(Q$1,""\d{4}"")),VALUE(REGEXEXTRACT(Q$1,""T(\d+)"")),1), monthEnd,EOMONTH(monthStart,0), actualStart,MAX($D3,monthStart), actualEnd,MIN($E3,monthEnd), workingDaysInMonth,NETWORKDAYS(monthStart,monthEnd), "&"workingDaysOverlap,IF(actualStart>actualEnd,0,NETWORKDAYS(actualStart,actualEnd)), IF(workingDaysOverlap=0,"""",$F3*workingDaysOverlap/workingDaysInMonth) )"),0.0) -> 0 | R3: =IFERROR(__xludf.DUMMYFUNCTION("LET( monthStart,DATE(VALUE(REGEXEXTRACT(R$1,""\d{4}"")),VALUE(REGEXEXTRACT(R$1,""T(\d+)"")),1), monthEnd,EOMONTH(monthStart,0), actualStart,MAX($D3,monthStart), actualEnd,MIN($E3,monthEnd), workingDaysInMonth,NETWORKDAYS(monthStart,monthEnd), "&"workingDaysOverlap,IF(actualStart>actualEnd,0,NETWORKDAYS(actualStart,actualEnd)), IF(workingDaysOverlap=0,"""",$F3*workingDaysOverlap/workingDaysInMonth) )"),0.0) -> 0 | S3: =IFERROR(__xludf.DUMMYFUNCTION("LET( monthStart,DATE(VALUE(REGEXEXTRACT(S$1,""\d{4}"")),VALUE(REGEXEXTRACT(S$1,""T(\d+)"")),1), monthEnd,EOMONTH(monthStart,0), actualStart,MAX($D3,monthStart), actualEnd,MIN($E3,monthEnd), workingDaysInMonth,NETWORKDAYS(monthStart,monthEnd), "&"workingDaysOverlap,IF(actualStart>actualEnd,0,NETWORKDAYS(actualStart,actualEnd)), IF(workingDaysOverlap=0,"""",$F3*workingDaysOverlap/workingDaysInMonth) )"),0.0) -> 0 | T3: =IFERROR(__xludf.DUMMYFUNCTION("LET( monthStart,DATE(VALUE(REGEXEXTRACT(T$1,""\d{4}"")),VALUE(REGEXEXTRACT(T$1,""T(\d+)"")),1), monthEnd,EOMONTH(monthStart,0), actualStart,MAX($D3,monthStart), actualEnd,MIN($E3,monthEnd), workingDaysInMonth,NETWORKDAYS(monthStart,monthEnd), "&"workingDaysOverlap,IF(actualStart>actualEnd,0,NETWORKDAYS(actualStart,actualEnd)), IF(workingDaysOverlap=0,"""",$F3*workingDaysOverlap/workingDaysInMonth) )"),0.0) -> 0 | U3: =IFERROR(__xludf.DUMMYFUNCTION("LET( monthStart,DATE(VALUE(REGEXEXTRACT(U$1,""\d{4}"")),VALUE(REGEXEXTRACT(U$1,""T(\d+)"")),1), monthEnd,EOMONTH(monthStart,0), actualStart,MAX($D3,monthStart), actualEnd,MIN($E3,monthEnd), workingDaysInMonth,NETWORKDAYS(monthStart,monthEnd), "&"workingDaysOverlap,IF(actualStart>actualEnd,0,NETWORKDAYS(actualStart,actualEnd)), IF(workingDaysOverlap=0,"""",$F3*workingDaysOverlap/workingDaysInMonth) )"),0.0) -> 0 | V3: =IFERROR(__xludf.DUMMYFUNCTION("LET( monthStart,DATE(VALUE(REGEXEXTRACT(V$1,""\d{4}"")),VALUE(REGEXEXTRACT(V$1,""T(\d+)"")),1), monthEnd,EOMONTH(monthStart,0), actualStart,MAX($D3,monthStart), actualEnd,MIN($E3,monthEnd), workingDaysInMonth,NETWORKDAYS(monthStart,monthEnd), "&"workingDaysOverlap,IF(actualStart>actualEnd,0,NETWORKDAYS(actualStart,actualEnd)), IF(workingDaysOverlap=0,"""",$F3*workingDaysOverlap/workingDaysInMonth) )"),0.0) -> 0 | W3: =IFERROR(__xludf.DUMMYFUNCTION("LET( monthStart,DATE(VALUE(REGEXEXTRACT(W$1,""\d{4}"")),VALUE(REGEXEXTRACT(W$1,""T(\d+)"")),1), monthEnd,EOMONTH(monthStart,0), actualStart,MAX($D3,monthStart), actualEnd,MIN($E3,monthEnd), workingDaysInMonth,NETWORKDAYS(monthStart,monthEnd), "&"workingDaysOverlap,IF(actualStart>actualEnd,0,NETWORKDAYS(actualStart,actualEnd)), IF(workingDaysOverlap=0,"""",$F3*workingDaysOverlap/workingDaysInMonth) )"),0.0) -> 0 | X3: =IFERROR(__xludf.DUMMYFUNCTION("LET( monthStart,DATE(VALUE(REGEXEXTRACT(X$1,""\d{4}"")),VALUE(REGEXEXTRACT(X$1,""T(\d+)"")),1), monthEnd,EOMONTH(monthStart,0), actualStart,MAX($D3,monthStart), actualEnd,MIN($E3,monthEnd), workingDaysInMonth,NETWORKDAYS(monthStart,monthEnd), "&"workingDaysOverlap,IF(actualStart>actualEnd,0,NETWORKDAYS(actualStart,actualEnd)), IF(workingDaysOverlap=0,"""",$F3*workingDaysOverlap/workingDaysInMonth) )"),0.0) -> 0 | Y3: =IFERROR(__xludf.DUMMYFUNCTION("LET( monthStart,DATE(VALUE(REGEXEXTRACT(Y$1,""\d{4}"")),VALUE(REGEXEXTRACT(Y$1,""T(\d+)"")),1), monthEnd,EOMONTH(monthStart,0), actualStart,MAX($D3,monthStart), actualEnd,MIN($E3,monthEnd), workingDaysInMonth,NETWORKDAYS(monthStart,monthEnd), "&"workingDaysOverlap,IF(actualStart>actualEnd,0,NETWORKDAYS(actualStart,actualEnd)), IF(workingDaysOverlap=0,"""",$F3*workingDaysOverlap/workingDaysInMonth) )"),0.0) -> 0
G4: =IFERROR(__xludf.DUMMYFUNCTION("LET( monthStart,DATE(VALUE(REGEXEXTRACT(G$1,""\d{4}"")),VALUE(REGEXEXTRACT(G$1,""T(\d+)"")),1), monthEnd,EOMONTH(monthStart,0), actualStart,MAX($D4,monthStart), actualEnd,MIN($E4,monthEnd), workingDaysInMonth,NETWORKDAYS(monthStart,monthEnd), "&"workingDaysOverlap,IF(actualStart>actualEnd,0,NETWORKDAYS(actualStart,actualEnd)), IF(workingDaysOverlap=0,"""",$F4*workingDaysOverlap/workingDaysInMonth) )"),0.0) -> 0 | H4: =IFERROR(__xludf.DUMMYFUNCTION("LET( monthStart,DATE(VALUE(REGEXEXTRACT(H$1,""\d{4}"")),VALUE(REGEXEXTRACT(H$1,""T(\d+)"")),1), monthEnd,EOMONTH(monthStart,0), actualStart,MAX($D4,monthStart), actualEnd,MIN($E4,monthEnd), workingDaysInMonth,NETWORKDAYS(monthStart,monthEnd), "&"workingDaysOverlap,IF(actualStart>actualEnd,0,NETWORKDAYS(actualStart,actualEnd)), IF(workingDaysOverlap=0,"""",$F4*workingDaysOverlap/workingDaysInMonth) )"),0.0) -> 0 | I4: =IFERROR(__xludf.DUMMYFUNCTION("LET( monthStart,DATE(VALUE(REGEXEXTRACT(I$1,""\d{4}"")),VALUE(REGEXEXTRACT(I$1,""T(\d+)"")),1), monthEnd,EOMONTH(monthStart,0), actualStart,MAX($D4,monthStart), actualEnd,MIN($E4,monthEnd), workingDaysInMonth,NETWORKDAYS(monthStart,monthEnd), "&"workingDaysOverlap,IF(actualStart>actualEnd,0,NETWORKDAYS(actualStart,actualEnd)), IF(workingDaysOverlap=0,"""",$F4*workingDaysOverlap/workingDaysInMonth) )"),0.0) -> 0 | J4: =IFERROR(__xludf.DUMMYFUNCTION("LET( monthStart,DATE(VALUE(REGEXEXTRACT(J$1,""\d{4}"")),VALUE(REGEXEXTRACT(J$1,""T(\d+)"")),1), monthEnd,EOMONTH(monthStart,0), actualStart,MAX($D4,monthStart), actualEnd,MIN($E4,monthEnd), workingDaysInMonth,NETWORKDAYS(monthStart,monthEnd), "&"workingDaysOverlap,IF(actualStart>actualEnd,0,NETWORKDAYS(actualStart,actualEnd)), IF(workingDaysOverlap=0,"""",$F4*workingDaysOverlap/workingDaysInMonth) )"),0.0) -> 0 | K4: =IFERROR(__xludf.DUMMYFUNCTION("LET( monthStart,DATE(VALUE(REGEXEXTRACT(K$1,""\d{4}"")),VALUE(REGEXEXTRACT(K$1,""T(\d+)"")),1), monthEnd,EOMONTH(monthStart,0), actualStart,MAX($D4,monthStart), actualEnd,MIN($E4,monthEnd), workingDaysInMonth,NETWORKDAYS(monthStart,monthEnd), "&"workingDaysOverlap,IF(actualStart>actualEnd,0,NETWORKDAYS(actualStart,actualEnd)), IF(workingDaysOverlap=0,"""",$F4*workingDaysOverlap/workingDaysInMonth) )"),0.0) -> 0 | L4: =IFERROR(__xludf.DUMMYFUNCTION("LET( monthStart,DATE(VALUE(REGEXEXTRACT(L$1,""\d{4}"")),VALUE(REGEXEXTRACT(L$1,""T(\d+)"")),1), monthEnd,EOMONTH(monthStart,0), actualStart,MAX($D4,monthStart), actualEnd,MIN($E4,monthEnd), workingDaysInMonth,NETWORKDAYS(monthStart,monthEnd), "&"workingDaysOverlap,IF(actualStart>actualEnd,0,NETWORKDAYS(actualStart,actualEnd)), IF(workingDaysOverlap=0,"""",$F4*workingDaysOverlap/workingDaysInMonth) )"),0.0) -> 0 | M4: =IFERROR(__xludf.DUMMYFUNCTION("LET( monthStart,DATE(VALUE(REGEXEXTRACT(M$1,""\d{4}"")),VALUE(REGEXEXTRACT(M$1,""T(\d+)"")),1), monthEnd,EOMONTH(monthStart,0), actualStart,MAX($D4,monthStart), actualEnd,MIN($E4,monthEnd), workingDaysInMonth,NETWORKDAYS(monthStart,monthEnd), "&"workingDaysOverlap,IF(actualStart>actualEnd,0,NETWORKDAYS(actualStart,actualEnd)), IF(workingDaysOverlap=0,"""",$F4*workingDaysOverlap/workingDaysInMonth) )"),0.0) -> 0 | N4: =IFERROR(__xludf.DUMMYFUNCTION("LET( monthStart,DATE(VALUE(REGEXEXTRACT(N$1,""\d{4}"")),VALUE(REGEXEXTRACT(N$1,""T(\d+)"")),1), monthEnd,EOMONTH(monthStart,0), actualStart,MAX($D4,monthStart), actualEnd,MIN($E4,monthEnd), workingDaysInMonth,NETWORKDAYS(monthStart,monthEnd), "&"workingDaysOverlap,IF(actualStart>actualEnd,0,NETWORKDAYS(actualStart,actualEnd)), IF(workingDaysOverlap=0,"""",$F4*workingDaysOverlap/workingDaysInMonth) )"),0.0) -> 0 | O4: =IFERROR(__xludf.DUMMYFUNCTION("LET( monthStart,DATE(VALUE(REGEXEXTRACT(O$1,""\d{4}"")),VALUE(REGEXEXTRACT(O$1,""T(\d+)"")),1), monthEnd,EOMONTH(monthStart,0), actualStart,MAX($D4,monthStart), actualEnd,MIN($E4,monthEnd), workingDaysInMonth,NETWORKDAYS(monthStart,monthEnd), "&"workingDaysOverlap,IF(actualStart>actualEnd,0,NETWORKDAYS(actualStart,actualEnd)), IF(workingDaysOverlap=0,"""",$F4*workingDaysOverlap/workingDaysInMonth) )"),0.0) -> 0 | P4: =IFERROR(__xludf.DUMMYFUNCTION("LET( monthStart,DATE(VALUE(REGEXEXTRACT(P$1,""\d{4}"")),VALUE(REGEXEXTRACT(P$1,""T(\d+)"")),1), monthEnd,EOMONTH(monthStart,0), actualStart,MAX($D4,monthStart), actualEnd,MIN($E4,monthEnd), workingDaysInMonth,NETWORKDAYS(monthStart,monthEnd), "&"workingDaysOverlap,IF(actualStart>actualEnd,0,NETWORKDAYS(actualStart,actualEnd)), IF(workingDaysOverlap=0,"""",$F4*workingDaysOverlap/workingDaysInMonth) )"),0.0) -> 0 | Q4: =IFERROR(__xludf.DUMMYFUNCTION("LET( monthStart,DATE(VALUE(REGEXEXTRACT(Q$1,""\d{4}"")),VALUE(REGEXEXTRACT(Q$1,""T(\d+)"")),1), monthEnd,EOMONTH(monthStart,0), actualStart,MAX($D4,monthStart), actualEnd,MIN($E4,monthEnd), workingDaysInMonth,NETWORKDAYS(monthStart,monthEnd), "&"workingDaysOverlap,IF(actualStart>actualEnd,0,NETWORKDAYS(actualStart,actualEnd)), IF(workingDaysOverlap=0,"""",$F4*workingDaysOverlap/workingDaysInMonth) )"),0.0) -> 0 | R4: =IFERROR(__xludf.DUMMYFUNCTION("LET( monthStart,DATE(VALUE(REGEXEXTRACT(R$1,""\d{4}"")),VALUE(REGEXEXTRACT(R$1,""T(\d+)"")),1), monthEnd,EOMONTH(monthStart,0), actualStart,MAX($D4,monthStart), actualEnd,MIN($E4,monthEnd), workingDaysInMonth,NETWORKDAYS(monthStart,monthEnd), "&"workingDaysOverlap,IF(actualStart>actualEnd,0,NETWORKDAYS(actualStart,actualEnd)), IF(workingDaysOverlap=0,"""",$F4*workingDaysOverlap/workingDaysInMonth) )"),0.0) -> 0 | S4: =IFERROR(__xludf.DUMMYFUNCTION("LET( monthStart,DATE(VALUE(REGEXEXTRACT(S$1,""\d{4}"")),VALUE(REGEXEXTRACT(S$1,""T(\d+)"")),1), monthEnd,EOMONTH(monthStart,0), actualStart,MAX($D4,monthStart), actualEnd,MIN($E4,monthEnd), workingDaysInMonth,NETWORKDAYS(monthStart,monthEnd), "&"workingDaysOverlap,IF(actualStart>actualEnd,0,NETWORKDAYS(actualStart,actualEnd)), IF(workingDaysOverlap=0,"""",$F4*workingDaysOverlap/workingDaysInMonth) )"),0.0) -> 0 | T4: =IFERROR(__xludf.DUMMYFUNCTION("LET( monthStart,DATE(VALUE(REGEXEXTRACT(T$1,""\d{4}"")),VALUE(REGEXEXTRACT(T$1,""T(\d+)"")),1), monthEnd,EOMONTH(monthStart,0), actualStart,MAX($D4,monthStart), actualEnd,MIN($E4,monthEnd), workingDaysInMonth,NETWORKDAYS(monthStart,monthEnd), "&"workingDaysOverlap,IF(actualStart>actualEnd,0,NETWORKDAYS(actualStart,actualEnd)), IF(workingDaysOverlap=0,"""",$F4*workingDaysOverlap/workingDaysInMonth) )"),0.0) -> 0 | U4: =IFERROR(__xludf.DUMMYFUNCTION("LET( monthStart,DATE(VALUE(REGEXEXTRACT(U$1,""\d{4}"")),VALUE(REGEXEXTRACT(U$1,""T(\d+)"")),1), monthEnd,EOMONTH(monthStart,0), actualStart,MAX($D4,monthStart), actualEnd,MIN($E4,monthEnd), workingDaysInMonth,NETWORKDAYS(monthStart,monthEnd), "&"workingDaysOverlap,IF(actualStart>actualEnd,0,NETWORKDAYS(actualStart,actualEnd)), IF(workingDaysOverlap=0,"""",$F4*workingDaysOverlap/workingDaysInMonth) )"),0.0) -> 0 | V4: =IFERROR(__xludf.DUMMYFUNCTION("LET( monthStart,DATE(VALUE(REGEXEXTRACT(V$1,""\d{4}"")),VALUE(REGEXEXTRACT(V$1,""T(\d+)"")),1), monthEnd,EOMONTH(monthStart,0), actualStart,MAX($D4,monthStart), actualEnd,MIN($E4,monthEnd), workingDaysInMonth,NETWORKDAYS(monthStart,monthEnd), "&"workingDaysOverlap,IF(actualStart>actualEnd,0,NETWORKDAYS(actualStart,actualEnd)), IF(workingDaysOverlap=0,"""",$F4*workingDaysOverlap/workingDaysInMonth) )"),0.0) -> 0 | W4: =IFERROR(__xludf.DUMMYFUNCTION("LET( monthStart,DATE(VALUE(REGEXEXTRACT(W$1,""\d{4}"")),VALUE(REGEXEXTRACT(W$1,""T(\d+)"")),1), monthEnd,EOMONTH(monthStart,0), actualStart,MAX($D4,monthStart), actualEnd,MIN($E4,monthEnd), workingDaysInMonth,NETWORKDAYS(monthStart,monthEnd), "&"workingDaysOverlap,IF(actualStart>actualEnd,0,NETWORKDAYS(actualStart,actualEnd)), IF(workingDaysOverlap=0,"""",$F4*workingDaysOverlap/workingDaysInMonth) )"),0.0) -> 0 | X4: =IFERROR(__xludf.DUMMYFUNCTION("LET( monthStart,DATE(VALUE(REGEXEXTRACT(X$1,""\d{4}"")),VALUE(REGEXEXTRACT(X$1,""T(\d+)"")),1), monthEnd,EOMONTH(monthStart,0), actualStart,MAX($D4,monthStart), actualEnd,MIN($E4,monthEnd), workingDaysInMonth,NETWORKDAYS(monthStart,monthEnd), "&"workingDaysOverlap,IF(actualStart>actualEnd,0,NETWORKDAYS(actualStart,actualEnd)), IF(workingDaysOverlap=0,"""",$F4*workingDaysOverlap/workingDaysInMonth) )"),0.0) -> 0 | Y4: =IFERROR(__xludf.DUMMYFUNCTION("LET( monthStart,DATE(VALUE(REGEXEXTRACT(Y$1,""\d{4}"")),VALUE(REGEXEXTRACT(Y$1,""T(\d+)"")),1), monthEnd,EOMONTH(monthStart,0), actualStart,MAX($D4,monthStart), actualEnd,MIN($E4,monthEnd), workingDaysInMonth,NETWORKDAYS(monthStart,monthEnd), "&"workingDaysOverlap,IF(actualStart>actualEnd,0,NETWORKDAYS(actualStart,actualEnd)), IF(workingDaysOverlap=0,"""",$F4*workingDaysOverlap/workingDaysInMonth) )"),0.0) -> 0
G5: =IFERROR(__xludf.DUMMYFUNCTION("LET( monthStart,DATE(VALUE(REGEXEXTRACT(G$1,""\d{4}"")),VALUE(REGEXEXTRACT(G$1,""T(\d+)"")),1), monthEnd,EOMONTH(monthStart,0), actualStart,MAX($D5,monthStart), actualEnd,MIN($E5,monthEnd), workingDaysInMonth,NETWORKDAYS(monthStart,monthEnd), "&"workingDaysOverlap,IF(actualStart>actualEnd,0,NETWORKDAYS(actualStart,actualEnd)), IF(workingDaysOverlap=0,"""",$F5*workingDaysOverlap/workingDaysInMonth) )"),0.0) -> 0 | H5: =IFERROR(__xludf.DUMMYFUNCTION("LET( monthStart,DATE(VALUE(REGEXEXTRACT(H$1,""\d{4}"")),VALUE(REGEXEXTRACT(H$1,""T(\d+)"")),1), monthEnd,EOMONTH(monthStart,0), actualStart,MAX($D5,monthStart), actualEnd,MIN($E5,monthEnd), workingDaysInMonth,NETWORKDAYS(monthStart,monthEnd), "&"workingDaysOverlap,IF(actualStart>actualEnd,0,NETWORKDAYS(actualStart,actualEnd)), IF(workingDaysOverlap=0,"""",$F5*workingDaysOverlap/workingDaysInMonth) )"),0.0) -> 0 | I5: =IFERROR(__xludf.DUMMYFUNCTION("LET( monthStart,DATE(VALUE(REGEXEXTRACT(I$1,""\d{4}"")),VALUE(REGEXEXTRACT(I$1,""T(\d+)"")),1), monthEnd,EOMONTH(monthStart,0), actualStart,MAX($D5,monthStart), actualEnd,MIN($E5,monthEnd), workingDaysInMonth,NETWORKDAYS(monthStart,monthEnd), "&"workingDaysOverlap,IF(actualStart>actualEnd,0,NETWORKDAYS(actualStart,actualEnd)), IF(workingDaysOverlap=0,"""",$F5*workingDaysOverlap/workingDaysInMonth) )"),0.0) -> 0 | J5: =IFERROR(__xludf.DUMMYFUNCTION("LET( monthStart,DATE(VALUE(REGEXEXTRACT(J$1,""\d{4}"")),VALUE(REGEXEXTRACT(J$1,""T(\d+)"")),1), monthEnd,EOMONTH(monthStart,0), actualStart,MAX($D5,monthStart), actualEnd,MIN($E5,monthEnd), workingDaysInMonth,NETWORKDAYS(monthStart,monthEnd), "&"workingDaysOverlap,IF(actualStart>actualEnd,0,NETWORKDAYS(actualStart,actualEnd)), IF(workingDaysOverlap=0,"""",$F5*workingDaysOverlap/workingDaysInMonth) )"),0.0) -> 0 | K5: =IFERROR(__xludf.DUMMYFUNCTION("LET( monthStart,DATE(VALUE(REGEXEXTRACT(K$1,""\d{4}"")),VALUE(REGEXEXTRACT(K$1,""T(\d+)"")),1), monthEnd,EOMONTH(monthStart,0), actualStart,MAX($D5,monthStart), actualEnd,MIN($E5,monthEnd), workingDaysInMonth,NETWORKDAYS(monthStart,monthEnd), "&"workingDaysOverlap,IF(actualStart>actualEnd,0,NETWORKDAYS(actualStart,actualEnd)), IF(workingDaysOverlap=0,"""",$F5*workingDaysOverlap/workingDaysInMonth) )"),0.0) -> 0 | L5: =IFERROR(__xludf.DUMMYFUNCTION("LET( monthStart,DATE(VALUE(REGEXEXTRACT(L$1,""\d{4}"")),VALUE(REGEXEXTRACT(L$1,""T(\d+)"")),1), monthEnd,EOMONTH(monthStart,0), actualStart,MAX($D5,monthStart), actualEnd,MIN($E5,monthEnd), workingDaysInMonth,NETWORKDAYS(monthStart,monthEnd), "&"workingDaysOverlap,IF(actualStart>actualEnd,0,NETWORKDAYS(actualStart,actualEnd)), IF(workingDaysOverlap=0,"""",$F5*workingDaysOverlap/workingDaysInMonth) )"),0.0) -> 0 | M5: =IFERROR(__xludf.DUMMYFUNCTION("LET( monthStart,DATE(VALUE(REGEXEXTRACT(M$1,""\d{4}"")),VALUE(REGEXEXTRACT(M$1,""T(\d+)"")),1), monthEnd,EOMONTH(monthStart,0), actualStart,MAX($D5,monthStart), actualEnd,MIN($E5,monthEnd), workingDaysInMonth,NETWORKDAYS(monthStart,monthEnd), "&"workingDaysOverlap,IF(actualStart>actualEnd,0,NETWORKDAYS(actualStart,actualEnd)), IF(workingDaysOverlap=0,"""",$F5*workingDaysOverlap/workingDaysInMonth) )"),0.0) -> 0 | N5: =IFERROR(__xludf.DUMMYFUNCTION("LET( monthStart,DATE(VALUE(REGEXEXTRACT(N$1,""\d{4}"")),VALUE(REGEXEXTRACT(N$1,""T(\d+)"")),1), monthEnd,EOMONTH(monthStart,0), actualStart,MAX($D5,monthStart), actualEnd,MIN($E5,monthEnd), workingDaysInMonth,NETWORKDAYS(monthStart,monthEnd), "&"workingDaysOverlap,IF(actualStart>actualEnd,0,NETWORKDAYS(actualStart,actualEnd)), IF(workingDaysOverlap=0,"""",$F5*workingDaysOverlap/workingDaysInMonth) )"),0.0) -> 0 | O5: =IFERROR(__xludf.DUMMYFUNCTION("LET( monthStart,DATE(VALUE(REGEXEXTRACT(O$1,""\d{4}"")),VALUE(REGEXEXTRACT(O$1,""T(\d+)"")),1), monthEnd,EOMONTH(monthStart,0), actualStart,MAX($D5,monthStart), actualEnd,MIN($E5,monthEnd), workingDaysInMonth,NETWORKDAYS(monthStart,monthEnd), "&"workingDaysOverlap,IF(actualStart>actualEnd,0,NETWORKDAYS(actualStart,actualEnd)), IF(workingDaysOverlap=0,"""",$F5*workingDaysOverlap/workingDaysInMonth) )"),0.0) -> 0 | P5: =IFERROR(__xludf.DUMMYFUNCTION("LET( monthStart,DATE(VALUE(REGEXEXTRACT(P$1,""\d{4}"")),VALUE(REGEXEXTRACT(P$1,""T(\d+)"")),1), monthEnd,EOMONTH(monthStart,0), actualStart,MAX($D5,monthStart), actualEnd,MIN($E5,monthEnd), workingDaysInMonth,NETWORKDAYS(monthStart,monthEnd), "&"workingDaysOverlap,IF(actualStart>actualEnd,0,NETWORKDAYS(actualStart,actualEnd)), IF(workingDaysOverlap=0,"""",$F5*workingDaysOverlap/workingDaysInMonth) )"),0.0) -> 0 | Q5: =IFERROR(__xludf.DUMMYFUNCTION("LET( monthStart,DATE(VALUE(REGEXEXTRACT(Q$1,""\d{4}"")),VALUE(REGEXEXTRACT(Q$1,""T(\d+)"")),1), monthEnd,EOMONTH(monthStart,0), actualStart,MAX($D5,monthStart), actualEnd,MIN($E5,monthEnd), workingDaysInMonth,NETWORKDAYS(monthStart,monthEnd), "&"workingDaysOverlap,IF(actualStart>actualEnd,0,NETWORKDAYS(actualStart,actualEnd)), IF(workingDaysOverlap=0,"""",$F5*workingDaysOverlap/workingDaysInMonth) )"),0.0) -> 0 | R5: =IFERROR(__xludf.DUMMYFUNCTION("LET( monthStart,DATE(VALUE(REGEXEXTRACT(R$1,""\d{4}"")),VALUE(REGEXEXTRACT(R$1,""T(\d+)"")),1), monthEnd,EOMONTH(monthStart,0), actualStart,MAX($D5,monthStart), actualEnd,MIN($E5,monthEnd), workingDaysInMonth,NETWORKDAYS(monthStart,monthEnd), "&"workingDaysOverlap,IF(actualStart>actualEnd,0,NETWORKDAYS(actualStart,actualEnd)), IF(workingDaysOverlap=0,"""",$F5*workingDaysOverlap/workingDaysInMonth) )"),0.0) -> 0 | S5: =IFERROR(__xludf.DUMMYFUNCTION("LET( monthStart,DATE(VALUE(REGEXEXTRACT(S$1,""\d{4}"")),VALUE(REGEXEXTRACT(S$1,""T(\d+)"")),1), monthEnd,EOMONTH(monthStart,0), actualStart,MAX($D5,monthStart), actualEnd,MIN($E5,monthEnd), workingDaysInMonth,NETWORKDAYS(monthStart,monthEnd), "&"workingDaysOverlap,IF(actualStart>actualEnd,0,NETWORKDAYS(actualStart,actualEnd)), IF(workingDaysOverlap=0,"""",$F5*workingDaysOverlap/workingDaysInMonth) )"),0.0) -> 0 | T5: =IFERROR(__xludf.DUMMYFUNCTION("LET( monthStart,DATE(VALUE(REGEXEXTRACT(T$1,""\d{4}"")),VALUE(REGEXEXTRACT(T$1,""T(\d+)"")),1), monthEnd,EOMONTH(monthStart,0), actualStart,MAX($D5,monthStart), actualEnd,MIN($E5,monthEnd), workingDaysInMonth,NETWORKDAYS(monthStart,monthEnd), "&"workingDaysOverlap,IF(actualStart>actualEnd,0,NETWORKDAYS(actualStart,actualEnd)), IF(workingDaysOverlap=0,"""",$F5*workingDaysOverlap/workingDaysInMonth) )"),0.0) -> 0 | U5: =IFERROR(__xludf.DUMMYFUNCTION("LET( monthStart,DATE(VALUE(REGEXEXTRACT(U$1,""\d{4}"")),VALUE(REGEXEXTRACT(U$1,""T(\d+)"")),1), monthEnd,EOMONTH(monthStart,0), actualStart,MAX($D5,monthStart), actualEnd,MIN($E5,monthEnd), workingDaysInMonth,NETWORKDAYS(monthStart,monthEnd), "&"workingDaysOverlap,IF(actualStart>actualEnd,0,NETWORKDAYS(actualStart,actualEnd)), IF(workingDaysOverlap=0,"""",$F5*workingDaysOverlap/workingDaysInMonth) )"),0.0) -> 0 | V5: =IFERROR(__xludf.DUMMYFUNCTION("LET( monthStart,DATE(VALUE(REGEXEXTRACT(V$1,""\d{4}"")),VALUE(REGEXEXTRACT(V$1,""T(\d+)"")),1), monthEnd,EOMONTH(monthStart,0), actualStart,MAX($D5,monthStart), actualEnd,MIN($E5,monthEnd), workingDaysInMonth,NETWORKDAYS(monthStart,monthEnd), "&"workingDaysOverlap,IF(actualStart>actualEnd,0,NETWORKDAYS(actualStart,actualEnd)), IF(workingDaysOverlap=0,"""",$F5*workingDaysOverlap/workingDaysInMonth) )"),0.0) -> 0 | W5: =IFERROR(__xludf.DUMMYFUNCTION("LET( monthStart,DATE(VALUE(REGEXEXTRACT(W$1,""\d{4}"")),VALUE(REGEXEXTRACT(W$1,""T(\d+)"")),1), monthEnd,EOMONTH(monthStart,0), actualStart,MAX($D5,monthStart), actualEnd,MIN($E5,monthEnd), workingDaysInMonth,NETWORKDAYS(monthStart,monthEnd), "&"workingDaysOverlap,IF(actualStart>actualEnd,0,NETWORKDAYS(actualStart,actualEnd)), IF(workingDaysOverlap=0,"""",$F5*workingDaysOverlap/workingDaysInMonth) )"),0.0) -> 0 | X5: =IFERROR(__xludf.DUMMYFUNCTION("LET( monthStart,DATE(VALUE(REGEXEXTRACT(X$1,""\d{4}"")),VALUE(REGEXEXTRACT(X$1,""T(\d+)"")),1), monthEnd,EOMONTH(monthStart,0), actualStart,MAX($D5,monthStart), actualEnd,MIN($E5,monthEnd), workingDaysInMonth,NETWORKDAYS(monthStart,monthEnd), "&"workingDaysOverlap,IF(actualStart>actualEnd,0,NETWORKDAYS(actualStart,actualEnd)), IF(workingDaysOverlap=0,"""",$F5*workingDaysOverlap/workingDaysInMonth) )"),0.0) -> 0 | Y5: =IFERROR(__xludf.DUMMYFUNCTION("LET( monthStart,DATE(VALUE(REGEXEXTRACT(Y$1,""\d{4}"")),VALUE(REGEXEXTRACT(Y$1,""T(\d+)"")),1), monthEnd,EOMONTH(monthStart,0), actualStart,MAX($D5,monthStart), actualEnd,MIN($E5,monthEnd), workingDaysInMonth,NETWORKDAYS(monthStart,monthEnd), "&"workingDaysOverlap,IF(actualStart>actualEnd,0,NETWORKDAYS(actualStart,actualEnd)), IF(workingDaysOverlap=0,"""",$F5*workingDaysOverlap/workingDaysInMonth) )"),0.0) -> 0
G6: =IFERROR(__xludf.DUMMYFUNCTION("LET( monthStart,DATE(VALUE(REGEXEXTRACT(G$1,""\d{4}"")),VALUE(REGEXEXTRACT(G$1,""T(\d+)"")),1), monthEnd,EOMONTH(monthStart,0), actualStart,MAX($D6,monthStart), actualEnd,MIN($E6,monthEnd), workingDaysInMonth,NETWORKDAYS(monthStart,monthEnd), "&"workingDaysOverlap,IF(actualStart>actualEnd,0,NETWORKDAYS(actualStart,actualEnd)), IF(workingDaysOverlap=0,"""",$F6*workingDaysOverlap/workingDaysInMonth) )"),0.0) -> 0 | H6: =IFERROR(__xludf.DUMMYFUNCTION("LET( monthStart,DATE(VALUE(REGEXEXTRACT(H$1,""\d{4}"")),VALUE(REGEXEXTRACT(H$1,""T(\d+)"")),1), monthEnd,EOMONTH(monthStart,0), actualStart,MAX($D6,monthStart), actualEnd,MIN($E6,monthEnd), workingDaysInMonth,NETWORKDAYS(monthStart,monthEnd), "&"workingDaysOverlap,IF(actualStart>actualEnd,0,NETWORKDAYS(actualStart,actualEnd)), IF(workingDaysOverlap=0,"""",$F6*workingDaysOverlap/workingDaysInMonth) )"),0.0) -> 0 | I6: =IFERROR(__xludf.DUMMYFUNCTION("LET( monthStart,DATE(VALUE(REGEXEXTRACT(I$1,""\d{4}"")),VALUE(REGEXEXTRACT(I$1,""T(\d+)"")),1), monthEnd,EOMONTH(monthStart,0), actualStart,MAX($D6,monthStart), actualEnd,MIN($E6,monthEnd), workingDaysInMonth,NETWORKDAYS(monthStart,monthEnd), "&"workingDaysOverlap,IF(actualStart>actualEnd,0,NETWORKDAYS(actualStart,actualEnd)), IF(workingDaysOverlap=0,"""",$F6*workingDaysOverlap/workingDaysInMonth) )"),0.0) -> 0 | J6: =IFERROR(__xludf.DUMMYFUNCTION("LET( monthStart,DATE(VALUE(REGEXEXTRACT(J$1,""\d{4}"")),VALUE(REGEXEXTRACT(J$1,""T(\d+)"")),1), monthEnd,EOMONTH(monthStart,0), actualStart,MAX($D6,monthStart), actualEnd,MIN($E6,monthEnd), workingDaysInMonth,NETWORKDAYS(monthStart,monthEnd), "&"workingDaysOverlap,IF(actualStart>actualEnd,0,NETWORKDAYS(actualStart,actualEnd)), IF(workingDaysOverlap=0,"""",$F6*workingDaysOverlap/workingDaysInMonth) )"),0.0) -> 0 | K6: =IFERROR(__xludf.DUMMYFUNCTION("LET( monthStart,DATE(VALUE(REGEXEXTRACT(K$1,""\d{4}"")),VALUE(REGEXEXTRACT(K$1,""T(\d+)"")),1), monthEnd,EOMONTH(monthStart,0), actualStart,MAX($D6,monthStart), actualEnd,MIN($E6,monthEnd), workingDaysInMonth,NETWORKDAYS(monthStart,monthEnd), "&"workingDaysOverlap,IF(actualStart>actualEnd,0,NETWORKDAYS(actualStart,actualEnd)), IF(workingDaysOverlap=0,"""",$F6*workingDaysOverlap/workingDaysInMonth) )"),0.0) -> 0 | L6: =IFERROR(__xludf.DUMMYFUNCTION("LET( monthStart,DATE(VALUE(REGEXEXTRACT(L$1,""\d{4}"")),VALUE(REGEXEXTRACT(L$1,""T(\d+)"")),1), monthEnd,EOMONTH(monthStart,0), actualStart,MAX($D6,monthStart), actualEnd,MIN($E6,monthEnd), workingDaysInMonth,NETWORKDAYS(monthStart,monthEnd), "&"workingDaysOverlap,IF(actualStart>actualEnd,0,NETWORKDAYS(actualStart,actualEnd)), IF(workingDaysOverlap=0,"""",$F6*workingDaysOverlap/workingDaysInMonth) )"),0.0) -> 0 | M6: =IFERROR(__xludf.DUMMYFUNCTION("LET( monthStart,DATE(VALUE(REGEXEXTRACT(M$1,""\d{4}"")),VALUE(REGEXEXTRACT(M$1,""T(\d+)"")),1), monthEnd,EOMONTH(monthStart,0), actualStart,MAX($D6,monthStart), actualEnd,MIN($E6,monthEnd), workingDaysInMonth,NETWORKDAYS(monthStart,monthEnd), "&"workingDaysOverlap,IF(actualStart>actualEnd,0,NETWORKDAYS(actualStart,actualEnd)), IF(workingDaysOverlap=0,"""",$F6*workingDaysOverlap/workingDaysInMonth) )"),0.0) -> 0 | N6: =IFERROR(__xludf.DUMMYFUNCTION("LET( monthStart,DATE(VALUE(REGEXEXTRACT(N$1,""\d{4}"")),VALUE(REGEXEXTRACT(N$1,""T(\d+)"")),1), monthEnd,EOMONTH(monthStart,0), actualStart,MAX($D6,monthStart), actualEnd,MIN($E6,monthEnd), workingDaysInMonth,NETWORKDAYS(monthStart,monthEnd), "&"workingDaysOverlap,IF(actualStart>actualEnd,0,NETWORKDAYS(actualStart,actualEnd)), IF(workingDaysOverlap=0,"""",$F6*workingDaysOverlap/workingDaysInMonth) )"),0.0) -> 0 | O6: =IFERROR(__xludf.DUMMYFUNCTION("LET( monthStart,DATE(VALUE(REGEXEXTRACT(O$1,""\d{4}"")),VALUE(REGEXEXTRACT(O$1,""T(\d+)"")),1), monthEnd,EOMONTH(monthStart,0), actualStart,MAX($D6,monthStart), actualEnd,MIN($E6,monthEnd), workingDaysInMonth,NETWORKDAYS(monthStart,monthEnd), "&"workingDaysOverlap,IF(actualStart>actualEnd,0,NETWORKDAYS(actualStart,actualEnd)), IF(workingDaysOverlap=0,"""",$F6*workingDaysOverlap/workingDaysInMonth) )"),0.0) -> 0 | P6: =IFERROR(__xludf.DUMMYFUNCTION("LET( monthStart,DATE(VALUE(REGEXEXTRACT(P$1,""\d{4}"")),VALUE(REGEXEXTRACT(P$1,""T(\d+)"")),1), monthEnd,EOMONTH(monthStart,0), actualStart,MAX($D6,monthStart), actualEnd,MIN($E6,monthEnd), workingDaysInMonth,NETWORKDAYS(monthStart,monthEnd), "&"workingDaysOverlap,IF(actualStart>actualEnd,0,NETWORKDAYS(actualStart,actualEnd)), IF(workingDaysOverlap=0,"""",$F6*workingDaysOverlap/workingDaysInMonth) )"),0.0) -> 0 | Q6: =IFERROR(__xludf.DUMMYFUNCTION("LET( monthStart,DATE(VALUE(REGEXEXTRACT(Q$1,""\d{4}"")),VALUE(REGEXEXTRACT(Q$1,""T(\d+)"")),1), monthEnd,EOMONTH(monthStart,0), actualStart,MAX($D6,monthStart), actualEnd,MIN($E6,monthEnd), workingDaysInMonth,NETWORKDAYS(monthStart,monthEnd), "&"workingDaysOverlap,IF(actualStart>actualEnd,0,NETWORKDAYS(actualStart,actualEnd)), IF(workingDaysOverlap=0,"""",$F6*workingDaysOverlap/workingDaysInMonth) )"),0.0) -> 0 | R6: =IFERROR(__xludf.DUMMYFUNCTION("LET( monthStart,DATE(VALUE(REGEXEXTRACT(R$1,""\d{4}"")),VALUE(REGEXEXTRACT(R$1,""T(\d+)"")),1), monthEnd,EOMONTH(monthStart,0), actualStart,MAX($D6,monthStart), actualEnd,MIN($E6,monthEnd), workingDaysInMonth,NETWORKDAYS(monthStart,monthEnd), "&"workingDaysOverlap,IF(actualStart>actualEnd,0,NETWORKDAYS(actualStart,actualEnd)), IF(workingDaysOverlap=0,"""",$F6*workingDaysOverlap/workingDaysInMonth) )"),0.0) -> 0 | S6: =IFERROR(__xludf.DUMMYFUNCTION("LET( monthStart,DATE(VALUE(REGEXEXTRACT(S$1,""\d{4}"")),VALUE(REGEXEXTRACT(S$1,""T(\d+)"")),1), monthEnd,EOMONTH(monthStart,0), actualStart,MAX($D6,monthStart), actualEnd,MIN($E6,monthEnd), workingDaysInMonth,NETWORKDAYS(monthStart,monthEnd), "&"workingDaysOverlap,IF(actualStart>actualEnd,0,NETWORKDAYS(actualStart,actualEnd)), IF(workingDaysOverlap=0,"""",$F6*workingDaysOverlap/workingDaysInMonth) )"),0.0) -> 0 | T6: =IFERROR(__xludf.DUMMYFUNCTION("LET( monthStart,DATE(VALUE(REGEXEXTRACT(T$1,""\d{4}"")),VALUE(REGEXEXTRACT(T$1,""T(\d+)"")),1), monthEnd,EOMONTH(monthStart,0), actualStart,MAX($D6,monthStart), actualEnd,MIN($E6,monthEnd), workingDaysInMonth,NETWORKDAYS(monthStart,monthEnd), "&"workingDaysOverlap,IF(actualStart>actualEnd,0,NETWORKDAYS(actualStart,actualEnd)), IF(workingDaysOverlap=0,"""",$F6*workingDaysOverlap/workingDaysInMonth) )"),0.0) -> 0 | U6: =IFERROR(__xludf.DUMMYFUNCTION("LET( monthStart,DATE(VALUE(REGEXEXTRACT(U$1,""\d{4}"")),VALUE(REGEXEXTRACT(U$1,""T(\d+)"")),1), monthEnd,EOMONTH(monthStart,0), actualStart,MAX($D6,monthStart), actualEnd,MIN($E6,monthEnd), workingDaysInMonth,NETWORKDAYS(monthStart,monthEnd), "&"workingDaysOverlap,IF(actualStart>actualEnd,0,NETWORKDAYS(actualStart,actualEnd)), IF(workingDaysOverlap=0,"""",$F6*workingDaysOverlap/workingDaysInMonth) )"),0.0) -> 0 | V6: =IFERROR(__xludf.DUMMYFUNCTION("LET( monthStart,DATE(VALUE(REGEXEXTRACT(V$1,""\d{4}"")),VALUE(REGEXEXTRACT(V$1,""T(\d+)"")),1), monthEnd,EOMONTH(monthStart,0), actualStart,MAX($D6,monthStart), actualEnd,MIN($E6,monthEnd), workingDaysInMonth,NETWORKDAYS(monthStart,monthEnd), "&"workingDaysOverlap,IF(actualStart>actualEnd,0,NETWORKDAYS(actualStart,actualEnd)), IF(workingDaysOverlap=0,"""",$F6*workingDaysOverlap/workingDaysInMonth) )"),0.0) -> 0 | W6: =IFERROR(__xludf.DUMMYFUNCTION("LET( monthStart,DATE(VALUE(REGEXEXTRACT(W$1,""\d{4}"")),VALUE(REGEXEXTRACT(W$1,""T(\d+)"")),1), monthEnd,EOMONTH(monthStart,0), actualStart,MAX($D6,monthStart), actualEnd,MIN($E6,monthEnd), workingDaysInMonth,NETWORKDAYS(monthStart,monthEnd), "&"workingDaysOverlap,IF(actualStart>actualEnd,0,NETWORKDAYS(actualStart,actualEnd)), IF(workingDaysOverlap=0,"""",$F6*workingDaysOverlap/workingDaysInMonth) )"),0.0) -> 0 | X6: =IFERROR(__xludf.DUMMYFUNCTION("LET( monthStart,DATE(VALUE(REGEXEXTRACT(X$1,""\d{4}"")),VALUE(REGEXEXTRACT(X$1,""T(\d+)"")),1), monthEnd,EOMONTH(monthStart,0), actualStart,MAX($D6,monthStart), actualEnd,MIN($E6,monthEnd), workingDaysInMonth,NETWORKDAYS(monthStart,monthEnd), "&"workingDaysOverlap,IF(actualStart>actualEnd,0,NETWORKDAYS(actualStart,actualEnd)), IF(workingDaysOverlap=0,"""",$F6*workingDaysOverlap/workingDaysInMonth) )"),0.0) -> 0 | Y6: =IFERROR(__xludf.DUMMYFUNCTION("LET( monthStart,DATE(VALUE(REGEXEXTRACT(Y$1,""\d{4}"")),VALUE(REGEXEXTRACT(Y$1,""T(\d+)"")),1), monthEnd,EOMONTH(monthStart,0), actualStart,MAX($D6,monthStart), actualEnd,MIN($E6,monthEnd), workingDaysInMonth,NETWORKDAYS(monthStart,monthEnd), "&"workingDaysOverlap,IF(actualStart>actualEnd,0,NETWORKDAYS(actualStart,actualEnd)), IF(workingDaysOverlap=0,"""",$F6*workingDaysOverlap/workingDaysInMonth) )"),0.0) -> 0
G7: =IFERROR(__xludf.DUMMYFUNCTION("LET( monthStart,DATE(VALUE(REGEXEXTRACT(G$1,""\d{4}"")),VALUE(REGEXEXTRACT(G$1,""T(\d+)"")),1), monthEnd,EOMONTH(monthStart,0), actualStart,MAX($D7,monthStart), actualEnd,MIN($E7,monthEnd), workingDaysInMonth,NETWORKDAYS(monthStart,monthEnd), "&"workingDaysOverlap,IF(actualStart>actualEnd,0,NETWORKDAYS(actualStart,actualEnd)), IF(workingDaysOverlap=0,"""",$F7*workingDaysOverlap/workingDaysInMonth) )"),0.0) -> 0 | H7: =IFERROR(__xludf.DUMMYFUNCTION("LET( monthStart,DATE(VALUE(REGEXEXTRACT(H$1,""\d{4}"")),VALUE(REGEXEXTRACT(H$1,""T(\d+)"")),1), monthEnd,EOMONTH(monthStart,0), actualStart,MAX($D7,monthStart), actualEnd,MIN($E7,monthEnd), workingDaysInMonth,NETWORKDAYS(monthStart,monthEnd), "&"workingDaysOverlap,IF(actualStart>actualEnd,0,NETWORKDAYS(actualStart,actualEnd)), IF(workingDaysOverlap=0,"""",$F7*workingDaysOverlap/workingDaysInMonth) )"),0.0) -> 0 | I7: =IFERROR(__xludf.DUMMYFUNCTION("LET( monthStart,DATE(VALUE(REGEXEXTRACT(I$1,""\d{4}"")),VALUE(REGEXEXTRACT(I$1,""T(\d+)"")),1), monthEnd,EOMONTH(monthStart,0), actualStart,MAX($D7,monthStart), actualEnd,MIN($E7,monthEnd), workingDaysInMonth,NETWORKDAYS(monthStart,monthEnd), "&"workingDaysOverlap,IF(actualStart>actualEnd,0,NETWORKDAYS(actualStart,actualEnd)), IF(workingDaysOverlap=0,"""",$F7*workingDaysOverlap/workingDaysInMonth) )"),0.0) -> 0 | J7: =IFERROR(__xludf.DUMMYFUNCTION("LET( monthStart,DATE(VALUE(REGEXEXTRACT(J$1,""\d{4}"")),VALUE(REGEXEXTRACT(J$1,""T(\d+)"")),1), monthEnd,EOMONTH(monthStart,0), actualStart,MAX($D7,monthStart), actualEnd,MIN($E7,monthEnd), workingDaysInMonth,NETWORKDAYS(monthStart,monthEnd), "&"workingDaysOverlap,IF(actualStart>actualEnd,0,NETWORKDAYS(actualStart,actualEnd)), IF(workingDaysOverlap=0,"""",$F7*workingDaysOverlap/workingDaysInMonth) )"),0.0) -> 0 | K7: =IFERROR(__xludf.DUMMYFUNCTION("LET( monthStart,DATE(VALUE(REGEXEXTRACT(K$1,""\d{4}"")),VALUE(REGEXEXTRACT(K$1,""T(\d+)"")),1), monthEnd,EOMONTH(monthStart,0), actualStart,MAX($D7,monthStart), actualEnd,MIN($E7,monthEnd), workingDaysInMonth,NETWORKDAYS(monthStart,monthEnd), "&"workingDaysOverlap,IF(actualStart>actualEnd,0,NETWORKDAYS(actualStart,actualEnd)), IF(workingDaysOverlap=0,"""",$F7*workingDaysOverlap/workingDaysInMonth) )"),0.0) -> 0 | L7: =IFERROR(__xludf.DUMMYFUNCTION("LET( monthStart,DATE(VALUE(REGEXEXTRACT(L$1,""\d{4}"")),VALUE(REGEXEXTRACT(L$1,""T(\d+)"")),1), monthEnd,EOMONTH(monthStart,0), actualStart,MAX($D7,monthStart), actualEnd,MIN($E7,monthEnd), workingDaysInMonth,NETWORKDAYS(monthStart,monthEnd), "&"workingDaysOverlap,IF(actualStart>actualEnd,0,NETWORKDAYS(actualStart,actualEnd)), IF(workingDaysOverlap=0,"""",$F7*workingDaysOverlap/workingDaysInMonth) )"),0.0) -> 0 | M7: =IFERROR(__xludf.DUMMYFUNCTION("LET( monthStart,DATE(VALUE(REGEXEXTRACT(M$1,""\d{4}"")),VALUE(REGEXEXTRACT(M$1,""T(\d+)"")),1), monthEnd,EOMONTH(monthStart,0), actualStart,MAX($D7,monthStart), actualEnd,MIN($E7,monthEnd), workingDaysInMonth,NETWORKDAYS(monthStart,monthEnd), "&"workingDaysOverlap,IF(actualStart>actualEnd,0,NETWORKDAYS(actualStart,actualEnd)), IF(workingDaysOverlap=0,"""",$F7*workingDaysOverlap/workingDaysInMonth) )"),0.0) -> 0 | N7: =IFERROR(__xludf.DUMMYFUNCTION("LET( monthStart,DATE(VALUE(REGEXEXTRACT(N$1,""\d{4}"")),VALUE(REGEXEXTRACT(N$1,""T(\d+)"")),1), monthEnd,EOMONTH(monthStart,0), actualStart,MAX($D7,monthStart), actualEnd,MIN($E7,monthEnd), workingDaysInMonth,NETWORKDAYS(monthStart,monthEnd), "&"workingDaysOverlap,IF(actualStart>actualEnd,0,NETWORKDAYS(actualStart,actualEnd)), IF(workingDaysOverlap=0,"""",$F7*workingDaysOverlap/workingDaysInMonth) )"),0.0) -> 0 | O7: =IFERROR(__xludf.DUMMYFUNCTION("LET( monthStart,DATE(VALUE(REGEXEXTRACT(O$1,""\d{4}"")),VALUE(REGEXEXTRACT(O$1,""T(\d+)"")),1), monthEnd,EOMONTH(monthStart,0), actualStart,MAX($D7,monthStart), actualEnd,MIN($E7,monthEnd), workingDaysInMonth,NETWORKDAYS(monthStart,monthEnd), "&"workingDaysOverlap,IF(actualStart>actualEnd,0,NETWORKDAYS(actualStart,actualEnd)), IF(workingDaysOverlap=0,"""",$F7*workingDaysOverlap/workingDaysInMonth) )"),0.0) -> 0 | P7: =IFERROR(__xludf.DUMMYFUNCTION("LET( monthStart,DATE(VALUE(REGEXEXTRACT(P$1,""\d{4}"")),VALUE(REGEXEXTRACT(P$1,""T(\d+)"")),1), monthEnd,EOMONTH(monthStart,0), actualStart,MAX($D7,monthStart), actualEnd,MIN($E7,monthEnd), workingDaysInMonth,NETWORKDAYS(monthStart,monthEnd), "&"workingDaysOverlap,IF(actualStart>actualEnd,0,NETWORKDAYS(actualStart,actualEnd)), IF(workingDaysOverlap=0,"""",$F7*workingDaysOverlap/workingDaysInMonth) )"),0.0) -> 0 | Q7: =IFERROR(__xludf.DUMMYFUNCTION("LET( monthStart,DATE(VALUE(REGEXEXTRACT(Q$1,""\d{4}"")),VALUE(REGEXEXTRACT(Q$1,""T(\d+)"")),1), monthEnd,EOMONTH(monthStart,0), actualStart,MAX($D7,monthStart), actualEnd,MIN($E7,monthEnd), workingDaysInMonth,NETWORKDAYS(monthStart,monthEnd), "&"workingDaysOverlap,IF(actualStart>actualEnd,0,NETWORKDAYS(actualStart,actualEnd)), IF(workingDaysOverlap=0,"""",$F7*workingDaysOverlap/workingDaysInMonth) )"),0.0) -> 0 | R7: =IFERROR(__xludf.DUMMYFUNCTION("LET( monthStart,DATE(VALUE(REGEXEXTRACT(R$1,""\d{4}"")),VALUE(REGEXEXTRACT(R$1,""T(\d+)"")),1), monthEnd,EOMONTH(monthStart,0), actualStart,MAX($D7,monthStart), actualEnd,MIN($E7,monthEnd), workingDaysInMonth,NETWORKDAYS(monthStart,monthEnd), "&"workingDaysOverlap,IF(actualStart>actualEnd,0,NETWORKDAYS(actualStart,actualEnd)), IF(workingDaysOverlap=0,"""",$F7*workingDaysOverlap/workingDaysInMonth) )"),0.0) -> 0 | S7: =IFERROR(__xludf.DUMMYFUNCTION("LET( monthStart,DATE(VALUE(REGEXEXTRACT(S$1,""\d{4}"")),VALUE(REGEXEXTRACT(S$1,""T(\d+)"")),1), monthEnd,EOMONTH(monthStart,0), actualStart,MAX($D7,monthStart), actualEnd,MIN($E7,monthEnd), workingDaysInMonth,NETWORKDAYS(monthStart,monthEnd), "&"workingDaysOverlap,IF(actualStart>actualEnd,0,NETWORKDAYS(actualStart,actualEnd)), IF(workingDaysOverlap=0,"""",$F7*workingDaysOverlap/workingDaysInMonth) )"),0.0) -> 0 | T7: =IFERROR(__xludf.DUMMYFUNCTION("LET( monthStart,DATE(VALUE(REGEXEXTRACT(T$1,""\d{4}"")),VALUE(REGEXEXTRACT(T$1,""T(\d+)"")),1), monthEnd,EOMONTH(monthStart,0), actualStart,MAX($D7,monthStart), actualEnd,MIN($E7,monthEnd), workingDaysInMonth,NETWORKDAYS(monthStart,monthEnd), "&"workingDaysOverlap,IF(actualStart>actualEnd,0,NETWORKDAYS(actualStart,actualEnd)), IF(workingDaysOverlap=0,"""",$F7*workingDaysOverlap/workingDaysInMonth) )"),0.0) -> 0 | U7: =IFERROR(__xludf.DUMMYFUNCTION("LET( monthStart,DATE(VALUE(REGEXEXTRACT(U$1,""\d{4}"")),VALUE(REGEXEXTRACT(U$1,""T(\d+)"")),1), monthEnd,EOMONTH(monthStart,0), actualStart,MAX($D7,monthStart), actualEnd,MIN($E7,monthEnd), workingDaysInMonth,NETWORKDAYS(monthStart,monthEnd), "&"workingDaysOverlap,IF(actualStart>actualEnd,0,NETWORKDAYS(actualStart,actualEnd)), IF(workingDaysOverlap=0,"""",$F7*workingDaysOverlap/workingDaysInMonth) )"),0.0) -> 0 | V7: =IFERROR(__xludf.DUMMYFUNCTION("LET( monthStart,DATE(VALUE(REGEXEXTRACT(V$1,""\d{4}"")),VALUE(REGEXEXTRACT(V$1,""T(\d+)"")),1), monthEnd,EOMONTH(monthStart,0), actualStart,MAX($D7,monthStart), actualEnd,MIN($E7,monthEnd), workingDaysInMonth,NETWORKDAYS(monthStart,monthEnd), "&"workingDaysOverlap,IF(actualStart>actualEnd,0,NETWORKDAYS(actualStart,actualEnd)), IF(workingDaysOverlap=0,"""",$F7*workingDaysOverlap/workingDaysInMonth) )"),0.0) -> 0 | W7: =IFERROR(__xludf.DUMMYFUNCTION("LET( monthStart,DATE(VALUE(REGEXEXTRACT(W$1,""\d{4}"")),VALUE(REGEXEXTRACT(W$1,""T(\d+)"")),1), monthEnd,EOMONTH(monthStart,0), actualStart,MAX($D7,monthStart), actualEnd,MIN($E7,monthEnd), workingDaysInMonth,NETWORKDAYS(monthStart,monthEnd), "&"workingDaysOverlap,IF(actualStart>actualEnd,0,NETWORKDAYS(actualStart,actualEnd)), IF(workingDaysOverlap=0,"""",$F7*workingDaysOverlap/workingDaysInMonth) )"),0.0) -> 0 | X7: =IFERROR(__xludf.DUMMYFUNCTION("LET( monthStart,DATE(VALUE(REGEXEXTRACT(X$1,""\d{4}"")),VALUE(REGEXEXTRACT(X$1,""T(\d+)"")),1), monthEnd,EOMONTH(monthStart,0), actualStart,MAX($D7,monthStart), actualEnd,MIN($E7,monthEnd), workingDaysInMonth,NETWORKDAYS(monthStart,monthEnd), "&"workingDaysOverlap,IF(actualStart>actualEnd,0,NETWORKDAYS(actualStart,actualEnd)), IF(workingDaysOverlap=0,"""",$F7*workingDaysOverlap/workingDaysInMonth) )"),0.0) -> 0 | Y7: =IFERROR(__xludf.DUMMYFUNCTION("LET( monthStart,DATE(VALUE(REGEXEXTRACT(Y$1,""\d{4}"")),VALUE(REGEXEXTRACT(Y$1,""T(\d+)"")),1), monthEnd,EOMONTH(monthStart,0), actualStart,MAX($D7,monthStart), actualEnd,MIN($E7,monthEnd), workingDaysInMonth,NETWORKDAYS(monthStart,monthEnd), "&"workingDaysOverlap,IF(actualStart>actualEnd,0,NETWORKDAYS(actualStart,actualEnd)), IF(workingDaysOverlap=0,"""",$F7*workingDaysOverlap/workingDaysInMonth) )"),0.0) -> 0
